[2024-10-18T02:31:51.372+0000] {local_task_job_runner.py:123} INFO - ::group::Pre task execution logs
[2024-10-18T02:31:51.380+0000] {taskinstance.py:2612} INFO - Dependencies all met for dep_context=non-requeueable deps ti=<TaskInstance: etl_reddit_pipeline.s3_upload manual__2024-10-18T02:31:47.475169+00:00 [queued]>
[2024-10-18T02:31:51.383+0000] {taskinstance.py:2612} INFO - Dependencies all met for dep_context=requeueable deps ti=<TaskInstance: etl_reddit_pipeline.s3_upload manual__2024-10-18T02:31:47.475169+00:00 [queued]>
[2024-10-18T02:31:51.384+0000] {taskinstance.py:2865} INFO - Starting attempt 1 of 1
[2024-10-18T02:31:51.388+0000] {taskinstance.py:2888} INFO - Executing <Task(PythonOperator): s3_upload> on 2024-10-18 02:31:47.475169+00:00
[2024-10-18T02:31:51.397+0000] {standard_task_runner.py:72} INFO - Started process 92 to run task
[2024-10-18T02:31:51.399+0000] {standard_task_runner.py:104} INFO - Running: ['airflow', 'tasks', 'run', 'etl_reddit_pipeline', 's3_upload', 'manual__2024-10-18T02:31:47.475169+00:00', '--job-id', '59', '--raw', '--subdir', 'DAGS_FOLDER/reddit_dag.py', '--cfg-path', '/tmp/tmpmvawwxhu']
[2024-10-18T02:31:51.400+0000] {standard_task_runner.py:105} INFO - Job 59: Subtask s3_upload
[2024-10-18T02:31:51.437+0000] {task_command.py:467} INFO - Running <TaskInstance: etl_reddit_pipeline.s3_upload manual__2024-10-18T02:31:47.475169+00:00 [running]> on host 7177c2697d25
[2024-10-18T02:31:51.474+0000] {taskinstance.py:3131} INFO - Exporting env vars: AIRFLOW_CTX_DAG_OWNER='Sushant' AIRFLOW_CTX_DAG_ID='etl_reddit_pipeline' AIRFLOW_CTX_TASK_ID='s3_upload' AIRFLOW_CTX_EXECUTION_DATE='2024-10-18T02:31:47.475169+00:00' AIRFLOW_CTX_TRY_NUMBER='1' AIRFLOW_CTX_DAG_RUN_ID='manual__2024-10-18T02:31:47.475169+00:00'
[2024-10-18T02:31:51.475+0000] {taskinstance.py:731} INFO - ::endgroup::
[2024-10-18T02:31:52.459+0000] {logging_mixin.py:190} INFO - Bucket already exists
[2024-10-18T02:31:52.719+0000] {taskinstance.py:3310} ERROR - Task failed with exception
Traceback (most recent call last):
  File "/home/airflow/.local/lib/python3.9/site-packages/s3fs/core.py", line 113, in _error_wrapper
    return await func(*args, **kwargs)
  File "/home/airflow/.local/lib/python3.9/site-packages/aiobotocore/client.py", line 412, in _make_api_call
    raise error_class(parsed_response, operation_name)
botocore.exceptions.ClientError: An error occurred (AccessDenied) when calling the PutObject operation: Access Denied

The above exception was the direct cause of the following exception:

Traceback (most recent call last):
  File "/home/airflow/.local/lib/python3.9/site-packages/airflow/models/taskinstance.py", line 767, in _execute_task
    result = _execute_callable(context=context, **execute_callable_kwargs)
  File "/home/airflow/.local/lib/python3.9/site-packages/airflow/models/taskinstance.py", line 733, in _execute_callable
    return ExecutionCallableRunner(
  File "/home/airflow/.local/lib/python3.9/site-packages/airflow/utils/operator_helpers.py", line 252, in run
    return self.func(*args, **kwargs)
  File "/home/airflow/.local/lib/python3.9/site-packages/airflow/models/baseoperator.py", line 406, in wrapper
    return func(self, *args, **kwargs)
  File "/home/airflow/.local/lib/python3.9/site-packages/airflow/operators/python.py", line 238, in execute
    return_value = self.execute_callable()
  File "/home/airflow/.local/lib/python3.9/site-packages/airflow/operators/python.py", line 256, in execute_callable
    return runner.run(*self.op_args, **self.op_kwargs)
  File "/home/airflow/.local/lib/python3.9/site-packages/airflow/utils/operator_helpers.py", line 252, in run
    return self.func(*args, **kwargs)
  File "/opt/airflow/pipelines/aws_s3_pipeline.py", line 10, in upload_s3_pipeline
    upload_to_s3(s3, file_path, AWS_BUCKET_NAME, file_path.split('/')[-1])
  File "/opt/airflow/etls/aws_etl.py", line 29, in upload_to_s3
    s3.put(file_path,bucket+'/raw/'+s3_file_name)
  File "/home/airflow/.local/lib/python3.9/site-packages/fsspec/asyn.py", line 118, in wrapper
    return sync(self.loop, func, *args, **kwargs)
  File "/home/airflow/.local/lib/python3.9/site-packages/fsspec/asyn.py", line 103, in sync
    raise return_result
  File "/home/airflow/.local/lib/python3.9/site-packages/fsspec/asyn.py", line 56, in _runner
    result[0] = await coro
  File "/home/airflow/.local/lib/python3.9/site-packages/fsspec/asyn.py", line 589, in _put
    return await _run_coros_in_chunks(
  File "/home/airflow/.local/lib/python3.9/site-packages/fsspec/asyn.py", line 268, in _run_coros_in_chunks
    result, k = await done.pop()
  File "/home/airflow/.local/lib/python3.9/site-packages/fsspec/asyn.py", line 245, in _run_coro
    return await asyncio.wait_for(coro, timeout=timeout), i
  File "/usr/local/lib/python3.9/asyncio/tasks.py", line 442, in wait_for
    return await fut
  File "/home/airflow/.local/lib/python3.9/site-packages/fsspec/callbacks.py", line 81, in func
    return await fn(path1, path2, callback=child, **kwargs)
  File "/home/airflow/.local/lib/python3.9/site-packages/s3fs/core.py", line 1196, in _put_file
    await self._call_s3(
  File "/home/airflow/.local/lib/python3.9/site-packages/s3fs/core.py", line 365, in _call_s3
    return await _error_wrapper(
  File "/home/airflow/.local/lib/python3.9/site-packages/s3fs/core.py", line 145, in _error_wrapper
    raise err
PermissionError: Access Denied
[2024-10-18T02:31:52.755+0000] {taskinstance.py:1225} INFO - Marking task as FAILED. dag_id=etl_reddit_pipeline, task_id=s3_upload, run_id=manual__2024-10-18T02:31:47.475169+00:00, execution_date=20241018T023147, start_date=20241018T023151, end_date=20241018T023152
[2024-10-18T02:31:52.778+0000] {taskinstance.py:340} INFO - ::group::Post task execution logs
[2024-10-18T02:31:52.778+0000] {standard_task_runner.py:124} ERROR - Failed to execute job 59 for task s3_upload (Access Denied; 92)
Traceback (most recent call last):
  File "/home/airflow/.local/lib/python3.9/site-packages/s3fs/core.py", line 113, in _error_wrapper
    return await func(*args, **kwargs)
  File "/home/airflow/.local/lib/python3.9/site-packages/aiobotocore/client.py", line 412, in _make_api_call
    raise error_class(parsed_response, operation_name)
botocore.exceptions.ClientError: An error occurred (AccessDenied) when calling the PutObject operation: Access Denied

The above exception was the direct cause of the following exception:

Traceback (most recent call last):
  File "/home/airflow/.local/lib/python3.9/site-packages/airflow/task/task_runner/standard_task_runner.py", line 117, in _start_by_fork
    ret = args.func(args, dag=self.dag)
  File "/home/airflow/.local/lib/python3.9/site-packages/airflow/cli/cli_config.py", line 49, in command
    return func(*args, **kwargs)
  File "/home/airflow/.local/lib/python3.9/site-packages/airflow/utils/cli.py", line 115, in wrapper
    return f(*args, **kwargs)
  File "/home/airflow/.local/lib/python3.9/site-packages/airflow/cli/commands/task_command.py", line 483, in task_run
    task_return_code = _run_task_by_selected_method(args, _dag, ti)
  File "/home/airflow/.local/lib/python3.9/site-packages/airflow/cli/commands/task_command.py", line 256, in _run_task_by_selected_method
    return _run_raw_task(args, ti)
  File "/home/airflow/.local/lib/python3.9/site-packages/airflow/cli/commands/task_command.py", line 341, in _run_raw_task
    return ti._run_raw_task(
  File "/home/airflow/.local/lib/python3.9/site-packages/airflow/utils/session.py", line 97, in wrapper
    return func(*args, session=session, **kwargs)
  File "/home/airflow/.local/lib/python3.9/site-packages/airflow/models/taskinstance.py", line 3004, in _run_raw_task
    return _run_raw_task(
  File "/home/airflow/.local/lib/python3.9/site-packages/airflow/models/taskinstance.py", line 273, in _run_raw_task
    TaskInstance._execute_task_with_callbacks(
  File "/home/airflow/.local/lib/python3.9/site-packages/airflow/models/taskinstance.py", line 3158, in _execute_task_with_callbacks
    result = self._execute_task(context, task_orig)
  File "/home/airflow/.local/lib/python3.9/site-packages/airflow/models/taskinstance.py", line 3182, in _execute_task
    return _execute_task(self, context, task_orig)
  File "/home/airflow/.local/lib/python3.9/site-packages/airflow/models/taskinstance.py", line 767, in _execute_task
    result = _execute_callable(context=context, **execute_callable_kwargs)
  File "/home/airflow/.local/lib/python3.9/site-packages/airflow/models/taskinstance.py", line 733, in _execute_callable
    return ExecutionCallableRunner(
  File "/home/airflow/.local/lib/python3.9/site-packages/airflow/utils/operator_helpers.py", line 252, in run
    return self.func(*args, **kwargs)
  File "/home/airflow/.local/lib/python3.9/site-packages/airflow/models/baseoperator.py", line 406, in wrapper
    return func(self, *args, **kwargs)
  File "/home/airflow/.local/lib/python3.9/site-packages/airflow/operators/python.py", line 238, in execute
    return_value = self.execute_callable()
  File "/home/airflow/.local/lib/python3.9/site-packages/airflow/operators/python.py", line 256, in execute_callable
    return runner.run(*self.op_args, **self.op_kwargs)
  File "/home/airflow/.local/lib/python3.9/site-packages/airflow/utils/operator_helpers.py", line 252, in run
    return self.func(*args, **kwargs)
  File "/opt/airflow/pipelines/aws_s3_pipeline.py", line 10, in upload_s3_pipeline
    upload_to_s3(s3, file_path, AWS_BUCKET_NAME, file_path.split('/')[-1])
  File "/opt/airflow/etls/aws_etl.py", line 29, in upload_to_s3
    s3.put(file_path,bucket+'/raw/'+s3_file_name)
  File "/home/airflow/.local/lib/python3.9/site-packages/fsspec/asyn.py", line 118, in wrapper
    return sync(self.loop, func, *args, **kwargs)
  File "/home/airflow/.local/lib/python3.9/site-packages/fsspec/asyn.py", line 103, in sync
    raise return_result
  File "/home/airflow/.local/lib/python3.9/site-packages/fsspec/asyn.py", line 56, in _runner
    result[0] = await coro
  File "/home/airflow/.local/lib/python3.9/site-packages/fsspec/asyn.py", line 589, in _put
    return await _run_coros_in_chunks(
  File "/home/airflow/.local/lib/python3.9/site-packages/fsspec/asyn.py", line 268, in _run_coros_in_chunks
    result, k = await done.pop()
  File "/home/airflow/.local/lib/python3.9/site-packages/fsspec/asyn.py", line 245, in _run_coro
    return await asyncio.wait_for(coro, timeout=timeout), i
  File "/usr/local/lib/python3.9/asyncio/tasks.py", line 442, in wait_for
    return await fut
  File "/home/airflow/.local/lib/python3.9/site-packages/fsspec/callbacks.py", line 81, in func
    return await fn(path1, path2, callback=child, **kwargs)
  File "/home/airflow/.local/lib/python3.9/site-packages/s3fs/core.py", line 1196, in _put_file
    await self._call_s3(
  File "/home/airflow/.local/lib/python3.9/site-packages/s3fs/core.py", line 365, in _call_s3
    return await _error_wrapper(
  File "/home/airflow/.local/lib/python3.9/site-packages/s3fs/core.py", line 145, in _error_wrapper
    raise err
PermissionError: Access Denied
[2024-10-18T02:31:52.832+0000] {local_task_job_runner.py:266} INFO - Task exited with return code 1
[2024-10-18T02:31:52.851+0000] {taskinstance.py:3900} INFO - 0 downstream tasks scheduled from follow-on schedule check
[2024-10-18T02:31:52.852+0000] {local_task_job_runner.py:245} INFO - ::endgroup::
