[2024-10-16T01:48:58.032+0000] {local_task_job_runner.py:123} INFO - ::group::Pre task execution logs
[2024-10-16T01:48:58.088+0000] {taskinstance.py:2612} INFO - Dependencies all met for dep_context=non-requeueable deps ti=<TaskInstance: etl_reddit_pipeline.reddit_extraction manual__2024-10-16T01:48:54.777680+00:00 [queued]>
[2024-10-16T01:48:58.098+0000] {taskinstance.py:2612} INFO - Dependencies all met for dep_context=requeueable deps ti=<TaskInstance: etl_reddit_pipeline.reddit_extraction manual__2024-10-16T01:48:54.777680+00:00 [queued]>
[2024-10-16T01:48:58.098+0000] {taskinstance.py:2865} INFO - Starting attempt 1 of 1
[2024-10-16T01:48:58.106+0000] {taskinstance.py:2888} INFO - Executing <Task(PythonOperator): reddit_extraction> on 2024-10-16 01:48:54.777680+00:00
[2024-10-16T01:48:58.115+0000] {standard_task_runner.py:72} INFO - Started process 49 to run task
[2024-10-16T01:48:58.135+0000] {standard_task_runner.py:104} INFO - Running: ['airflow', 'tasks', 'run', 'etl_reddit_pipeline', 'reddit_extraction', 'manual__2024-10-16T01:48:54.777680+00:00', '--job-id', '30', '--raw', '--subdir', 'DAGS_FOLDER/reddit_dag.py', '--cfg-path', '/tmp/tmpygfi_vhz']
[2024-10-16T01:48:58.141+0000] {standard_task_runner.py:105} INFO - Job 30: Subtask reddit_extraction
[2024-10-16T01:48:58.241+0000] {task_command.py:467} INFO - Running <TaskInstance: etl_reddit_pipeline.reddit_extraction manual__2024-10-16T01:48:54.777680+00:00 [running]> on host 02292e6002a1
[2024-10-16T01:48:58.370+0000] {taskinstance.py:3131} INFO - Exporting env vars: AIRFLOW_CTX_DAG_OWNER='Sushant' AIRFLOW_CTX_DAG_ID='etl_reddit_pipeline' AIRFLOW_CTX_TASK_ID='reddit_extraction' AIRFLOW_CTX_EXECUTION_DATE='2024-10-16T01:48:54.777680+00:00' AIRFLOW_CTX_TRY_NUMBER='1' AIRFLOW_CTX_DAG_RUN_ID='manual__2024-10-16T01:48:54.777680+00:00'
[2024-10-16T01:48:58.372+0000] {taskinstance.py:731} INFO - ::endgroup::
[2024-10-16T01:48:58.433+0000] {taskinstance.py:3310} ERROR - Task failed with exception
Traceback (most recent call last):
  File "/home/airflow/.local/lib/python3.9/site-packages/airflow/models/taskinstance.py", line 767, in _execute_task
    result = _execute_callable(context=context, **execute_callable_kwargs)
  File "/home/airflow/.local/lib/python3.9/site-packages/airflow/models/taskinstance.py", line 733, in _execute_callable
    return ExecutionCallableRunner(
  File "/home/airflow/.local/lib/python3.9/site-packages/airflow/utils/operator_helpers.py", line 252, in run
    return self.func(*args, **kwargs)
  File "/home/airflow/.local/lib/python3.9/site-packages/airflow/models/baseoperator.py", line 406, in wrapper
    return func(self, *args, **kwargs)
  File "/home/airflow/.local/lib/python3.9/site-packages/airflow/operators/python.py", line 238, in execute
    return_value = self.execute_callable()
  File "/home/airflow/.local/lib/python3.9/site-packages/airflow/operators/python.py", line 256, in execute_callable
    return runner.run(*self.op_args, **self.op_kwargs)
  File "/home/airflow/.local/lib/python3.9/site-packages/airflow/utils/operator_helpers.py", line 252, in run
    return self.func(*args, **kwargs)
  File "/opt/airflow/pipelines/reddit_pipeline.py", line 7, in reddit_pipeline
    conn = BaseHook.get_connection('reddit_api')
  File "/home/airflow/.local/lib/python3.9/site-packages/airflow/hooks/base.py", line 83, in get_connection
    conn = Connection.get_connection_from_secrets(conn_id)
  File "/home/airflow/.local/lib/python3.9/site-packages/airflow/models/connection.py", line 537, in get_connection_from_secrets
    raise AirflowNotFoundException(f"The conn_id `{conn_id}` isn't defined")
airflow.exceptions.AirflowNotFoundException: The conn_id `reddit_api` isn't defined
[2024-10-16T01:48:58.445+0000] {taskinstance.py:1225} INFO - Marking task as FAILED. dag_id=etl_reddit_pipeline, task_id=reddit_extraction, run_id=manual__2024-10-16T01:48:54.777680+00:00, execution_date=20241016T014854, start_date=20241016T014858, end_date=20241016T014858
[2024-10-16T01:48:58.462+0000] {taskinstance.py:340} INFO - ::group::Post task execution logs
[2024-10-16T01:48:58.463+0000] {standard_task_runner.py:124} ERROR - Failed to execute job 30 for task reddit_extraction (The conn_id `reddit_api` isn't defined; 49)
Traceback (most recent call last):
  File "/home/airflow/.local/lib/python3.9/site-packages/airflow/task/task_runner/standard_task_runner.py", line 117, in _start_by_fork
    ret = args.func(args, dag=self.dag)
  File "/home/airflow/.local/lib/python3.9/site-packages/airflow/cli/cli_config.py", line 49, in command
    return func(*args, **kwargs)
  File "/home/airflow/.local/lib/python3.9/site-packages/airflow/utils/cli.py", line 115, in wrapper
    return f(*args, **kwargs)
  File "/home/airflow/.local/lib/python3.9/site-packages/airflow/cli/commands/task_command.py", line 483, in task_run
    task_return_code = _run_task_by_selected_method(args, _dag, ti)
  File "/home/airflow/.local/lib/python3.9/site-packages/airflow/cli/commands/task_command.py", line 256, in _run_task_by_selected_method
    return _run_raw_task(args, ti)
  File "/home/airflow/.local/lib/python3.9/site-packages/airflow/cli/commands/task_command.py", line 341, in _run_raw_task
    return ti._run_raw_task(
  File "/home/airflow/.local/lib/python3.9/site-packages/airflow/utils/session.py", line 97, in wrapper
    return func(*args, session=session, **kwargs)
  File "/home/airflow/.local/lib/python3.9/site-packages/airflow/models/taskinstance.py", line 3004, in _run_raw_task
    return _run_raw_task(
  File "/home/airflow/.local/lib/python3.9/site-packages/airflow/models/taskinstance.py", line 273, in _run_raw_task
    TaskInstance._execute_task_with_callbacks(
  File "/home/airflow/.local/lib/python3.9/site-packages/airflow/models/taskinstance.py", line 3158, in _execute_task_with_callbacks
    result = self._execute_task(context, task_orig)
  File "/home/airflow/.local/lib/python3.9/site-packages/airflow/models/taskinstance.py", line 3182, in _execute_task
    return _execute_task(self, context, task_orig)
  File "/home/airflow/.local/lib/python3.9/site-packages/airflow/models/taskinstance.py", line 767, in _execute_task
    result = _execute_callable(context=context, **execute_callable_kwargs)
  File "/home/airflow/.local/lib/python3.9/site-packages/airflow/models/taskinstance.py", line 733, in _execute_callable
    return ExecutionCallableRunner(
  File "/home/airflow/.local/lib/python3.9/site-packages/airflow/utils/operator_helpers.py", line 252, in run
    return self.func(*args, **kwargs)
  File "/home/airflow/.local/lib/python3.9/site-packages/airflow/models/baseoperator.py", line 406, in wrapper
    return func(self, *args, **kwargs)
  File "/home/airflow/.local/lib/python3.9/site-packages/airflow/operators/python.py", line 238, in execute
    return_value = self.execute_callable()
  File "/home/airflow/.local/lib/python3.9/site-packages/airflow/operators/python.py", line 256, in execute_callable
    return runner.run(*self.op_args, **self.op_kwargs)
  File "/home/airflow/.local/lib/python3.9/site-packages/airflow/utils/operator_helpers.py", line 252, in run
    return self.func(*args, **kwargs)
  File "/opt/airflow/pipelines/reddit_pipeline.py", line 7, in reddit_pipeline
    conn = BaseHook.get_connection('reddit_api')
  File "/home/airflow/.local/lib/python3.9/site-packages/airflow/hooks/base.py", line 83, in get_connection
    conn = Connection.get_connection_from_secrets(conn_id)
  File "/home/airflow/.local/lib/python3.9/site-packages/airflow/models/connection.py", line 537, in get_connection_from_secrets
    raise AirflowNotFoundException(f"The conn_id `{conn_id}` isn't defined")
airflow.exceptions.AirflowNotFoundException: The conn_id `reddit_api` isn't defined
[2024-10-16T01:48:58.498+0000] {local_task_job_runner.py:266} INFO - Task exited with return code 1
[2024-10-16T01:48:58.512+0000] {taskinstance.py:3900} INFO - 0 downstream tasks scheduled from follow-on schedule check
[2024-10-16T01:48:58.512+0000] {local_task_job_runner.py:245} INFO - ::endgroup::
